Workbook

Sheet Lists
A1: Tracker Lists
A2: Validation lists used across the workbook.
A3: Status | B3: Yes/No | C3: Priority | D3: Source | E3: Colour stage | F3: Assessment tag | G3: Method | H3: Energy
A4: Not started | B4: No | C4: Critical | D4: Textbook | E4: Purple | F4: A1 | G4: Read | H4: Low
A5: Planned | B5: Yes | C5: High | D5: Slides | E5: Dark Blue | F5: A2 | G5: Paper notes | H5: Medium
A6: Reading | C6: Medium | D6: Tutorial | E6: Light Blue | F6: Both | G6: Self-explain x1 | H6: High
A7: Paper notes done | C7: Low | D7: Graph | E7: Dark Green | F7: Optional | G7: Self-explain x2
A8: Self-explain x1 | C8: Parking Lot | D8: Merged | E8: Pastel Green | G8: Teach-back
A9: Self-explain x2 | D9: Own notes | E9: Pastel Yellow | G9: Tutorial practice
A10: Teach-back done | D10: Assessment scope | E10: Orange | G10: Graph drill
A11: Tutorial done | D11: Past paper | E11: Red | G11: Mixed revision
A12: Graphs mastered | D12: Class note | E12: Pink | G12: Mock test

Sheet Unit 1 Tracker
A1: Unit 1 — major-topic tracker
A2: Main editable tracker: use the stage columns for execution and the time estimates for day planning.
A4: Topic ID | B4: Unit | C4: Topic / subtopic | D4: Section colour | E4: Source | F4: A1 tag | G4: A2 tag | H4: Priority | I4: Confidence (1-5) | J4: Scheduled? | K4: Read once? | L4: Paper notes? | M4: Explain x1? | N4: Explain x2? | O4: Teach-back? | P4: Tutorial done? | Q4: Graph mastery? | R4: Exam ready? | S4: Need revisit? | T4: Status | U4: Est read mins | V4: Est notes mins | W4: Est explain mins | X4: Est tutorial mins | Y4: Est graph mins | Z4: Est total mins | AA4: Progress % | AB4: Time remaining mins | AC4: Next action | AD4: Notes
A5: U1-01 | B5: Unit 1 | C5: GDP, GDP per capita, and history's hockey stick | D5: Purple | E5: Merged | F5: A1 | H5: Critical | I5: 1 | J5: Yes | K5: Yes | L5: Yes | M5: No | N5: No | O5: No | P5: No | Q5: No | R5: No | S5: Yes | T5: Paper notes done | U5: 20 | V5: 35 | W5: 20 | X5: 20 | Y5: 20 | Z5: =SUM(U5:Y5) -> 115 | AA5: =COUNTIF(K5:R5,"Yes")/8 -> 0.25 | AB5: =Z5*(1-AA5) -> 86.25 | AC5: Start with definitions + hockey-stick graph
A6: U1-02 | B6: Unit 1 | C6: Limits of GDP as a measure of wellbeing | D6: Dark Blue | E6: Merged | F6: A1 | H6: High | I6: 1 | J6: Yes | K6: Yes | L6: Yes | M6: No | N6: No | O6: No | P6: No | Q6: No | R6: No | S6: No | T6: Reading | U6: 15 | V6: 25 | W6: 15 | X6: 10 | Y6: 10 | Z6: =SUM(U6:Y6) -> 75 | AA6: =COUNTIF(K6:R6,"Yes")/8 -> 0.25 | AB6: =Z6*(1-AA6) -> 56.25 | AC6: List what GDP misses
A7: U1-03 | B7: Unit 1 | C7: Climate change and the cost of economic development | D7: Light Blue | E7: Merged | F7: A1 | H7: High | I7: 1 | J7: Yes | K7: Yes | L7: No | M7: No | N7: No | O7: No | P7: No | Q7: No | R7: No | S7: No | T7: Planned | U7: 15 | V7: 25 | W7: 20 | X7: 10 | Y7: 15 | Z7: =SUM(U7:Y7) -> 85 | AA7: =COUNTIF(K7:R7,"Yes")/8 -> 0.125 | AB7: =Z7*(1-AA7) -> 74.375 | AC7: Tie growth to environmental cost
A8: U1-04 | B8: Unit 1 | C8: Between-country and within-country inequality | D8: Dark Green | E8: Merged | F8: A1 | H8: High | I8: 1 | J8: No | K8: Yes | L8: No | M8: No | N8: No | O8: No | P8: No | Q8: No | R8: No | S8: No | T8: Planned | U8: 15 | V8: 30 | W8: 20 | X8: 15 | Y8: 20 | Z8: =SUM(U8:Y8) -> 100 | AA8: =COUNTIF(K8:R8,"Yes")/8 -> 0.125 | AB8: =Z8*(1-AA8) -> 87.5 | AC8: Explain averages vs distribution
A9: U1-05 | B9: Unit 1 | C9: Continuous technological revolution | D9: Pastel Green | E9: Merged | F9: A1 | H9: Medium | I9: 1 | J9: No | K9: Yes | L9: No | M9: No | N9: No | O9: No | P9: No | Q9: No | R9: No | S9: No | T9: Planned | U9: 15 | V9: 25 | W9: 20 | X9: 10 | Y9: 10 | Z9: =SUM(U9:Y9) -> 80 | AA9: =COUNTIF(K9:R9,"Yes")/8 -> 0.125 | AB9: =Z9*(1-AA9) -> 70 | AC9: Use historical + modern examples
A10: U1-06 | B10: Unit 1 | C10: Production function and diminishing average product of labour | D10: Pastel Yellow | E10: Merged | F10: A1 | H10: Critical | I10: 1 | J10: No | K10: No | L10: No | M10: No | N10: No | O10: No | P10: No | Q10: No | R10: No | S10: No | T10: Planned | U10: 20 | V10: 30 | W10: 25 | X10: 20 | Y10: 20 | Z10: =SUM(U10:Y10) -> 115 | AA10: =COUNTIF(K10:R10,"Yes")/8 -> 0 | AB10: =Z10*(1-AA10) -> 115 | AC10: Separate total output from output per worker
A11: U1-07 | B11: Unit 1 | C11: Malthusian trap, subsistence, and technology shock | D11: Orange | E11: Merged | F11: A1 | H11: Critical | I11: 1 | J11: No | K11: No | L11: No | M11: No | N11: No | O11: No | P11: No | Q11: No | R11: No | S11: No | T11: Planned | U11: 25 | V11: 35 | W11: 30 | X11: 25 | Y11: 25 | Z11: =SUM(U11:Y11) -> 140 | AA11: =COUNTIF(K11:R11,"Yes")/8 -> 0 | AB11: =Z11*(1-AA11) -> 140 | AC11: Practise the four-step mechanism aloud
A12: U1-08 | B12: Unit 1 | C12: Capitalism, institutions, and structural transformation | D12: Red | E12: Merged | F12: A1 | H12: Critical | I12: 1 | J12: No | K12: No | L12: No | M12: No | N12: No | O12: No | P12: No | Q12: No | R12: No | S12: No | T12: Planned | U12: 25 | V12: 40 | W12: 30 | X12: 20 | Y12: 15 | Z12: =SUM(U12:Y12) -> 130 | AA12: =COUNTIF(K12:R12,"Yes")/8 -> 0 | AB12: =Z12*(1-AA12) -> 130 | AC12: Use private property + firms + markets
A13: U1-09 | B13: Unit 1 | C13: Colonization, varieties of capitalism, and the biosphere | D13: Pink | E13: Merged | F13: A1 | H13: High | I13: 1 | J13: No | K13: No | L13: No | M13: No | N13: No | O13: No | P13: No | Q13: No | R13: No | S13: No | T13: Planned | U13: 25 | V13: 40 | W13: 30 | X13: 20 | Y13: 20 | Z13: =SUM(U13:Y13) -> 135 | AA13: =COUNTIF(K13:R13,"Yes")/8 -> 0 | AB13: =Z13*(1-AA13) -> 135 | AC13: Link history, institutions, and environmental limits

Sheet Unit 2 Tracker
A1: Unit 2 — major-topic tracker
A2: Main editable tracker: use the stage columns for execution and the time estimates for day planning.
A4: Topic ID | B4: Unit | C4: Topic / subtopic | D4: Section colour | E4: Source | F4: A1 tag | G4: A2 tag | H4: Priority | I4: Confidence (1-5) | J4: Scheduled? | K4: Read once? | L4: Paper notes? | M4: Explain x1? | N4: Explain x2? | O4: Teach-back? | P4: Tutorial done? | Q4: Graph mastery? | R4: Exam ready? | S4: Need revisit? | T4: Status | U4: Est read mins | V4: Est notes mins | W4: Est explain mins | X4: Est tutorial mins | Y4: Est graph mins | Z4: Est total mins | AA4: Progress % | AB4: Time remaining mins | AC4: Next action | AD4: Notes
A5: U2-01 | B5: Unit 2 | C5: Kutesmart, automation, and the opening technology story | D5: Purple | E5: Merged | F5: A1 | H5: Medium | I5: 1 | J5: No | K5: No | L5: No | M5: No | N5: No | O5: No | P5: No | Q5: No | R5: No | S5: No | T5: Not started | U5: 15 | V5: 20 | W5: 15 | X5: 10 | Y5: 10 | Z5: =SUM(U5:Y5) -> 70 | AA5: =COUNTIF(K5:R5,"Yes")/8 -> 0 | AB5: =Z5*(1-AA5) -> 70 | AC5: Use it as the intuition for the whole unit
A6: U2-02 | B6: Unit 2 | C6: Opportunity cost, economic cost, reservation option, and economic rent | D6: Dark Blue | E6: Merged | F6: A1 | H6: Critical | I6: 1 | J6: No | K6: No | L6: No | M6: No | N6: No | O6: No | P6: No | Q6: No | R6: No | S6: No | T6: Not started | U6: 25 | V6: 35 | W6: 25 | X6: 25 | Y6: 10 | Z6: =SUM(U6:Y6) -> 120 | AA6: =COUNTIF(K6:R6,"Yes")/8 -> 0 | AB6: =Z6*(1-AA6) -> 120 | AC6: Practise the Sipho/concert-style logic
A7: U2-03 | B7: Unit 2 | C7: Relative prices | D7: Light Blue | E7: Merged | F7: A1 | H7: High | I7: 1 | J7: No | K7: No | L7: No | M7: No | N7: No | O7: No | P7: No | Q7: No | R7: No | S7: No | T7: Not started | U7: 15 | V7: 25 | W7: 20 | X7: 20 | Y7: 10 | Z7: =SUM(U7:Y7) -> 90 | AA7: =COUNTIF(K7:R7,"Yes")/8 -> 0 | AB7: =Z7*(1-AA7) -> 90 | AC7: Compare money price vs relative price
A8: U2-04 | B8: Unit 2 | C8: Comparative advantage, specialization, and division of labour | D8: Dark Green | E8: Merged | F8: A1 | H8: Critical | I8: 1 | J8: No | K8: No | L8: No | M8: No | N8: No | O8: No | P8: No | Q8: No | R8: No | S8: No | T8: Not started | U8: 25 | V8: 35 | W8: 25 | X8: 20 | Y8: 20 | Z8: =SUM(U8:Y8) -> 125 | AA8: =COUNTIF(K8:R8,"Yes")/8 -> 0 | AB8: =Z8*(1-AA8) -> 125 | AC8: Always talk in terms of opportunity cost
A9: U2-05 | B9: Unit 2 | C9: Firms, technology, production, and dominated technologies | D9: Pastel Green | E9: Merged | F9: A1 | H9: High | I9: 1 | J9: No | K9: No | L9: No | M9: No | N9: No | O9: No | P9: No | Q9: No | R9: No | S9: No | T9: Not started | U9: 20 | V9: 35 | W9: 25 | X9: 20 | Y9: 20 | Z9: =SUM(U9:Y9) -> 120 | AA9: =COUNTIF(K9:R9,"Yes")/8 -> 0 | AB9: =Z9*(1-AA9) -> 120 | AC9: Dominated ≠ cheapest, explain both
A10: U2-06 | B10: Unit 2 | C10: Isocost logic and cost-minimizing technology choice | D10: Pastel Yellow | E10: Merged | F10: A1 | H10: Critical | I10: 1 | J10: No | K10: No | L10: No | M10: No | N10: No | O10: No | P10: No | Q10: No | R10: No | S10: No | T10: Not started | U10: 20 | V10: 35 | W10: 30 | X10: 25 | Y10: 25 | Z10: =SUM(U10:Y10) -> 135 | AA10: =COUNTIF(K10:R10,"Yes")/8 -> 0 | AB10: =Z10*(1-AA10) -> 135 | AC10: Use wage/capital-price changes carefully
A11: U2-07 | B11: Unit 2 | C11: Innovation and profit / innovation rents | D11: Orange | E11: Merged | F11: A1 | H11: Medium | I11: 1 | J11: No | K11: No | L11: No | M11: No | N11: No | O11: No | P11: No | Q11: No | R11: No | S11: No | T11: Not started | U11: 15 | V11: 25 | W11: 20 | X11: 15 | Y11: 10 | Z11: =SUM(U11:Y11) -> 85 | AA11: =COUNTIF(K11:R11,"Yes")/8 -> 0 | AB11: =Z11*(1-AA11) -> 85 | AC11: Remember rents are temporary
A12: U2-08 | B12: Unit 2 | C12: Cheap coal, expensive labour, and the Industrial Revolution | D12: Red | E12: Merged | F12: A1 | H12: Critical | I12: 1 | J12: No | K12: No | L12: No | M12: No | N12: No | O12: No | P12: No | Q12: No | R12: No | S12: No | T12: Not started | U12: 25 | V12: 40 | W12: 30 | X12: 20 | Y12: 20 | Z12: =SUM(U12:Y12) -> 135 | AA12: =COUNTIF(K12:R12,"Yes")/8 -> 0 | AB12: =Z12*(1-AA12) -> 135 | AC12: Explain incentives, not just inventions
A13: U2-09 | B13: Unit 2 | C13: Escape from the Malthusian trap, growth, and capitalism + carbon | D13: Pink | E13: Merged | F13: A1 | H13: High | I13: 1 | J13: No | K13: No | L13: No | M13: No | N13: No | O13: No | P13: No | Q13: No | R13: No | S13: No | T13: Not started | U13: 20 | V13: 35 | W13: 25 | X13: 20 | Y13: 20 | Z13: =SUM(U13:Y13) -> 120 | AA13: =COUNTIF(K13:R13,"Yes")/8 -> 0 | AB13: =Z13*(1-AA13) -> 120 | AC13: Connect back to Unit 1 clearly

Sheet Unit 3 Tracker
A1: Unit 3 — major-topic tracker
A2: Main editable tracker: use the stage columns for execution and the time estimates for day planning.
A4: Topic ID | B4: Unit | C4: Topic / subtopic | D4: Section colour | E4: Source | F4: A1 tag | G4: A2 tag | H4: Priority | I4: Confidence (1-5) | J4: Scheduled? | K4: Read once? | L4: Paper notes? | M4: Explain x1? | N4: Explain x2? | O4: Teach-back? | P4: Tutorial done? | Q4: Graph mastery? | R4: Exam ready? | S4: Need revisit? | T4: Status | U4: Est read mins | V4: Est notes mins | W4: Est explain mins | X4: Est tutorial mins | Y4: Est graph mins | Z4: Est total mins | AA4: Progress % | AB4: Time remaining mins | AC4: Next action | AD4: Notes
A5: U3-01 | B5: Unit 3 | C5: Scarcity and the consumer-choice model | D5: Purple | E5: Merged | F5: A1 | H5: High | I5: 1 | J5: No | K5: No | L5: No | M5: No | N5: No | O5: No | P5: No | Q5: No | R5: No | S5: No | T5: Not started | U5: 15 | V5: 25 | W5: 20 | X5: 10 | Y5: 10 | Z5: =SUM(U5:Y5) -> 80 | AA5: =COUNTIF(K5:R5,"Yes")/8 -> 0 | AB5: =Z5*(1-AA5) -> 80 | AC5: Always say preferences + constraints
A6: U3-02 | B6: Unit 3 | C6: Preferences, utility, indifference curves, and diminishing MRS | D6: Dark Blue | E6: Merged | F6: A1 | H6: Critical | I6: 1 | J6: No | K6: No | L6: No | M6: No | N6: No | O6: No | P6: No | Q6: No | R6: No | S6: No | T6: Not started | U6: 25 | V6: 40 | W6: 30 | X6: 20 | Y6: 25 | Z6: =SUM(U6:Y6) -> 140 | AA6: =COUNTIF(K6:R6,"Yes")/8 -> 0 | AB6: =Z6*(1-AA6) -> 140 | AC6: Do not let ICs shift when budget changes
A7: U3-03 | B7: Unit 3 | C7: Budget constraints, feasible sets, MRT, and relative prices | D7: Light Blue | E7: Merged | F7: A1 | H7: Critical | I7: 1 | J7: No | K7: No | L7: No | M7: No | N7: No | O7: No | P7: No | Q7: No | R7: No | S7: No | T7: Not started | U7: 25 | V7: 35 | W7: 30 | X7: 25 | Y7: 25 | Z7: =SUM(U7:Y7) -> 140 | AA7: =COUNTIF(K7:R7,"Yes")/8 -> 0 | AB7: =Z7*(1-AA7) -> 140 | AC7: Write the line equation from scratch
A8: U3-04 | B8: Unit 3 | C8: Optimal choice and MRS = MRT | D8: Dark Green | E8: Merged | F8: A1 | H8: Critical | I8: 1 | J8: No | K8: No | L8: No | M8: No | N8: No | O8: No | P8: No | Q8: No | R8: No | S8: No | T8: Not started | U8: 20 | V8: 30 | W8: 25 | X8: 20 | Y8: 20 | Z8: =SUM(U8:Y8) -> 115 | AA8: =COUNTIF(K8:R8,"Yes")/8 -> 0 | AB8: =Z8*(1-AA8) -> 115 | AC8: Explain highest attainable IC
A9: U3-05 | B9: Unit 3 | C9: Price effect, income effect, and substitution effect for goods | D9: Pastel Green | E9: Merged | F9: A1 | H9: Critical | I9: 1 | J9: No | K9: No | L9: No | M9: No | N9: No | O9: No | P9: No | Q9: No | R9: No | S9: No | T9: Not started | U9: 25 | V9: 40 | W9: 35 | X9: 25 | Y9: 25 | Z9: =SUM(U9:Y9) -> 150 | AA9: =COUNTIF(K9:R9,"Yes")/8 -> 0 | AB9: =Z9*(1-AA9) -> 150 | AC9: Be able to separate the two effects cleanly
A10: U3-06 | B10: Unit 3 | C10: Work, free time, and the labour-supply model | D10: Pastel Yellow | E10: Merged | F10: A1 | H10: High | I10: 1 | J10: No | K10: No | L10: No | M10: No | N10: No | O10: No | P10: No | Q10: No | R10: No | S10: No | T10: Not started | U10: 20 | V10: 35 | W10: 30 | X10: 20 | Y10: 20 | Z10: =SUM(U10:Y10) -> 125 | AA10: =COUNTIF(K10:R10,"Yes")/8 -> 0 | AB10: =Z10*(1-AA10) -> 125 | AC10: Wage is the opportunity cost of free time
A11: U3-07 | B11: Unit 3 | C11: Wage changes: income vs substitution effects on hours worked | D11: Orange | E11: Merged | F11: A1 | H11: Critical | I11: 1 | J11: No | K11: No | L11: No | M11: No | N11: No | O11: No | P11: No | Q11: No | R11: No | S11: No | T11: Not started | U11: 25 | V11: 35 | W11: 30 | X11: 20 | Y11: 25 | Z11: =SUM(U11:Y11) -> 135 | AA11: =COUNTIF(K11:R11,"Yes")/8 -> 0 | AB11: =Z11*(1-AA11) -> 135 | AC11: Dominant effect depends on behaviour
A12: U3-08 | B12: Unit 3 | C12: Model limits, country differences, and long-run changes in work hours | D12: Pink | E12: Merged | F12: A1 | H12: Medium | I12: 1 | J12: No | K12: No | L12: No | M12: No | N12: No | O12: No | P12: No | Q12: No | R12: No | S12: No | T12: Not started | U12: 20 | V12: 30 | W12: 20 | X12: 15 | Y12: 10 | Z12: =SUM(U12:Y12) -> 95 | AA12: =COUNTIF(K12:R12,"Yes")/8 -> 0 | AB12: =Z12*(1-AA12) -> 95 | AC12: Give one strength and one limitation

Sheet Unit 4 Tracker
A1: Unit 4 — major-topic tracker
A2: Main editable tracker: use the stage columns for execution and the time estimates for day planning.
A4: Topic ID | B4: Unit | C4: Topic / subtopic | D4: Section colour | E4: Source | F4: A1 tag | G4: A2 tag | H4: Priority | I4: Confidence (1-5) | J4: Scheduled? | K4: Read once? | L4: Paper notes? | M4: Explain x1? | N4: Explain x2? | O4: Teach-back? | P4: Tutorial done? | Q4: Graph mastery? | R4: Exam ready? | S4: Need revisit? | T4: Status | U4: Est read mins | V4: Est notes mins | W4: Est explain mins | X4: Est tutorial mins | Y4: Est graph mins | Z4: Est total mins | AA4: Progress % | AB4: Time remaining mins | AC4: Next action | AD4: Notes
A5: U4-01 | B5: Unit 4 | C5: Climate negotiations, social dilemmas, and tragedy of the commons | D5: Purple | E5: Merged | F5: A1 | H5: Critical | I5: 1 | J5: No | K5: No | L5: No | M5: No | N5: No | O5: No | P5: No | Q5: No | R5: No | S5: No | T5: Not started | U5: 20 | V5: 30 | W5: 25 | X5: 15 | Y5: 10 | Z5: =SUM(U5:Y5) -> 100 | AA5: =COUNTIF(K5:R5,"Yes")/8 -> 0 | AB5: =Z5*(1-AA5) -> 100 | AC5: Start with the definition of a social dilemma
A6: U4-02 | B6: Unit 4 | C6: Game theory basics: players, strategies, payoffs, information | D6: Dark Blue | E6: Merged | F6: A1 | H6: Critical | I6: 1 | J6: No | K6: No | L6: No | M6: No | N6: No | O6: No | P6: No | Q6: No | R6: No | S6: No | T6: Not started | U6: 20 | V6: 30 | W6: 25 | X6: 20 | Y6: 15 | Z6: =SUM(U6:Y6) -> 110 | AA6: =COUNTIF(K6:R6,"Yes")/8 -> 0 | AB6: =Z6*(1-AA6) -> 110 | AC6: Read matrices carefully before solving
A7: U4-03 | B7: Unit 4 | C7: Best responses, invisible-hand games, and Nash equilibrium | D7: Light Blue | E7: Merged | F7: A1 | H7: Critical | I7: 1 | J7: No | K7: No | L7: No | M7: No | N7: No | O7: No | P7: No | Q7: No | R7: No | S7: No | T7: Not started | U7: 25 | V7: 35 | W7: 30 | X7: 20 | Y7: 20 | Z7: =SUM(U7:Y7) -> 130 | AA7: =COUNTIF(K7:R7,"Yes")/8 -> 0 | AB7: =Z7*(1-AA7) -> 130 | AC7: Best response first, equilibrium second
A8: U4-04 | B8: Unit 4 | C8: Dominant strategies and prisoners' dilemmas | D8: Dark Green | E8: Merged | F8: A1 | H8: Critical | I8: 1 | J8: No | K8: No | L8: No | M8: No | N8: No | O8: No | P8: No | Q8: No | R8: No | S8: No | T8: Not started | U8: 25 | V8: 35 | W8: 30 | X8: 20 | Y8: 20 | Z8: =SUM(U8:Y8) -> 130 | AA8: =COUNTIF(K8:R8,"Yes")/8 -> 0 | AB8: =Z8*(1-AA8) -> 130 | AC8: Show why stable can still be socially bad
A9: U4-05 | B9: Unit 4 | C9: Pareto criterion, Pareto efficiency, and fairness | D9: Pastel Green | E9: Merged | F9: A1 | H9: High | I9: 1 | J9: No | K9: No | L9: No | M9: No | N9: No | O9: No | P9: No | Q9: No | R9: No | S9: No | T9: Not started | U9: 20 | V9: 30 | W9: 25 | X9: 20 | Y9: 15 | Z9: =SUM(U9:Y9) -> 110 | AA9: =COUNTIF(K9:R9,"Yes")/8 -> 0 | AB9: =Z9*(1-AA9) -> 110 | AC9: Pareto efficient is not the same as fair
A10: U4-06 | B10: Unit 4 | C10: Public-good games, free-riding, and Ostrom | D10: Pastel Yellow | E10: Merged | F10: A1 | H10: High | I10: 1 | J10: No | K10: No | L10: No | M10: No | N10: No | O10: No | P10: No | Q10: No | R10: No | S10: No | T10: Not started | U10: 25 | V10: 40 | W10: 30 | X10: 20 | Y10: 15 | Z10: =SUM(U10:Y10) -> 130 | AA10: =COUNTIF(K10:R10,"Yes")/8 -> 0 | AB10: =Z10*(1-AA10) -> 130 | AC10: Common property is not the same as open access
A11: U4-07 | B11: Unit 4 | C11: Social preferences: altruism, reciprocity, inequality aversion | D11: Orange | E11: Merged | F11: A1 | H11: High | I11: 1 | J11: No | K11: No | L11: No | M11: No | N11: No | O11: No | P11: No | Q11: No | R11: No | S11: No | T11: Not started | U11: 20 | V11: 35 | W11: 30 | X11: 20 | Y11: 15 | Z11: =SUM(U11:Y11) -> 120 | AA11: =COUNTIF(K11:R11,"Yes")/8 -> 0 | AB11: =Z11*(1-AA11) -> 120 | AC11: Explain how utility changes, not just behaviour
A12: U4-08 | B12: Unit 4 | C12: Repeated interaction, experiments, punishment, and crowding out | D12: Red | E12: Merged | F12: A1 | H12: High | I12: 1 | J12: No | K12: No | L12: No | M12: No | N12: No | O12: No | P12: No | Q12: No | R12: No | S12: No | T12: Not started | U12: 25 | V12: 40 | W12: 30 | X12: 25 | Y12: 15 | Z12: =SUM(U12:Y12) -> 135 | AA12: =COUNTIF(K12:R12,"Yes")/8 -> 0 | AB12: =Z12*(1-AA12) -> 135 | AC12: Use day-care fine and punishment experiments
A13: U4-09 | B13: Unit 4 | C13: Cooperation, negotiation, and conflicts of interest | D13: Pink | E13: Merged | F13: A1 | H13: Medium | I13: 1 | J13: No | K13: No | L13: No | M13: No | N13: No | O13: No | P13: No | Q13: No | R13: No | S13: No | T13: Not started | U13: 20 | V13: 30 | W13: 25 | X13: 20 | Y13: 10 | Z13: =SUM(U13:Y13) -> 105 | AA13: =COUNTIF(K13:R13,"Yes")/8 -> 0 | AB13: =Z13*(1-AA13) -> 105 | AC13: Explain mutual gain vs bargaining over division
A14: U4-10 | B14: Unit 4 | C14: Ultimatum game, experiments, expected payoffs, and competition | D14: Purple | E14: Merged | F14: A1 | H14: Critical | I14: 1 | J14: No | K14: No | L14: No | M14: No | N14: No | O14: No | P14: No | Q14: No | R14: No | S14: No | T14: Not started | U14: 30 | V14: 45 | W14: 35 | X14: 25 | Y14: 20 | Z14: =SUM(U14:Y14) -> 155 | AA14: =COUNTIF(K14:R14,"Yes")/8 -> 0 | AB14: =Z14*(1-AA14) -> 155 | AC14: Sequential solve first, then experimental results
A15: U4-11 | B15: Unit 4 | C15: Coordination games, hawk–dove, and climate-change modelling | D15: Dark Blue | E15: Merged | F15: A1 | H15: Critical | I15: 1 | J15: No | K15: No | L15: No | M15: No | N15: No | O15: No | P15: No | Q15: No | R15: No | S15: No | T15: Not started | U15: 30 | V15: 45 | W15: 35 | X15: 25 | Y15: 20 | Z15: =SUM(U15:Y15) -> 155 | AA15: =COUNTIF(K15:R15,"Yes")/8 -> 0 | AB15: =Z15*(1-AA15) -> 155 | AC15: Distinguish PD vs coordination vs hawk–dove

Sheet Master Planner
A1: Master Planner — linked roll-up
A2: Read-only consolidation of all unit trackers. Edit the Unit 1–4 sheets, not this one.
A4: Topic ID | B4: Unit | C4: Topic / subtopic | D4: Section colour | E4: Source | F4: A1 tag | G4: A2 tag | H4: Priority | I4: Confidence (1-5) | J4: Scheduled? | K4: Read once? | L4: Paper notes? | M4: Explain x1? | N4: Explain x2? | O4: Teach-back? | P4: Tutorial done? | Q4: Graph mastery? | R4: Exam ready? | S4: Need revisit? | T4: Status | U4: Est read mins | V4: Est notes mins | W4: Est explain mins | X4: Est tutorial mins | Y4: Est graph mins | Z4: Est total mins | AA4: Progress % | AB4: Time remaining mins | AC4: Next action | AD4: Notes | AE4: Priority score | AF4: Task score
A5: ='Unit 1 Tracker'!A5 -> U1-01 | B5: ='Unit 1 Tracker'!B5 -> Unit 1 | C5: ='Unit 1 Tracker'!C5 -> GDP, GDP per capita, and history's hockey stick | D5: ='Unit 1 Tracker'!D5 -> Purple | E5: ='Unit 1 Tracker'!E5 -> Merged | F5: ='Unit 1 Tracker'!F5 -> A1 | G5: ='Unit 1 Tracker'!G5 -> 0 | H5: ='Unit 1 Tracker'!H5 -> Critical | ... AD5: ='Unit 1 Tracker'!AD5 -> 0 | AE5: =IF(H5="Critical",4,IF(H5="High",3,IF(H5="Medium",2,IF(H5="Low",1,0)))) -> 4 | AF5: =(1-AA5)*100+AE5*8+IF(I5<=2,8,0) -> 115
A6: ='Unit 1 Tracker'!A6 -> U1-02 | B6: ='Unit 1 Tracker'!B6 -> Unit 1 | C6: ='Unit 1 Tracker'!C6 -> Limits of GDP as a measure of wellbeing | D6: ='Unit 1 Tracker'!D6 -> Dark Blue | E6: ='Unit 1 Tracker'!E6 -> Merged | F6: ='Unit 1 Tracker'!F6 -> A1 | G6: ='Unit 1 Tracker'!G6 -> 0 | H6: ='Unit 1 Tracker'!H6 -> High | ... AD6: ='Unit 1 Tracker'!AD6 -> 0 | AE6: =IF(H6="Critical",4,IF(H6="High",3,IF(H6="Medium",2,IF(H6="Low",1,0)))) -> 3 | AF6: =(1-AA6)*100+AE6*8+IF(I6<=2,8,0) -> 107
A7: ='Unit 1 Tracker'!A7 -> U1-03 | B7: ='Unit 1 Tracker'!B7 -> Unit 1 | C7: ='Unit 1 Tracker'!C7 -> Climate change and the cost of economic development | D7: ='Unit 1 Tracker'!D7 -> Light Blue | E7: ='Unit 1 Tracker'!E7 -> Merged | F7: ='Unit 1 Tracker'!F7 -> A1 | G7: ='Unit 1 Tracker'!G7 -> 0 | H7: ='Unit 1 Tracker'!H7 -> High | ... AD7: ='Unit 1 Tracker'!AD7 -> 0 | AE7: =IF(H7="Critical",4,IF(H7="High",3,IF(H7="Medium",2,IF(H7="Low",1,0)))) -> 3 | AF7: =(1-AA7)*100+AE7*8+IF(I7<=2,8,0) -> 119.5
A8: ='Unit 1 Tracker'!A8 -> U1-04 | B8: ='Unit 1 Tracker'!B8 -> Unit 1 | C8: ='Unit 1 Tracker'!C8 -> Between-country and within-country inequality | D8: ='Unit 1 Tracker'!D8 -> Dark Green | E8: ='Unit 1 Tracker'!E8 -> Merged | F8: ='Unit 1 Tracker'!F8 -> A1 | G8: ='Unit 1 Tracker'!G8 -> 0 | H8: ='Unit 1 Tracker'!H8 -> High | ... AD8: ='Unit 1 Tracker'!AD8 -> 0 | AE8: =IF(H8="Critical",4,IF(H8="High",3,IF(H8="Medium",2,IF(H8="Low",1,0)))) -> 3 | AF8: =(1-AA8)*100+AE8*8+IF(I8<=2,8,0) -> 119.5
A9: ='Unit 1 Tracker'!A9 -> U1-05 | B9: ='Unit 1 Tracker'!B9 -> Unit 1 | C9: ='Unit 1 Tracker'!C9 -> Continuous technological revolution | D9: ='Unit 1 Tracker'!D9 -> Pastel Green | E9: ='Unit 1 Tracker'!E9 -> Merged | F9: ='Unit 1 Tracker'!F9 -> A1 | G9: ='Unit 1 Tracker'!G9 -> 0 | H9: ='Unit 1 Tracker'!H9 -> Medium | ... AD9: ='Unit 1 Tracker'!AD9 -> 0 | AE9: =IF(H9="Critical",4,IF(H9="High",3,IF(H9="Medium",2,IF(H9="Low",1,0)))) -> 2 | AF9: =(1-AA9)*100+AE9*8+IF(I9<=2,8,0) -> 111.5
A10: ='Unit 1 Tracker'!A10 -> U1-06 | B10: ='Unit 1 Tracker'!B10 -> Unit 1 | C10: ='Unit 1 Tracker'!C10 -> Production function and diminishing average product of labour | D10: ='Unit 1 Tracker'!D10 -> Pastel Yellow | E10: ='Unit 1 Tracker'!E10 -> Merged | F10: ='Unit 1 Tracker'!F10 -> A1 | G10: ='Unit 1 Tracker'!G10 -> 0 | H10: ='Unit 1 Tracker'!H10 -> Critical | ... AD10: ='Unit 1 Tracker'!AD10 -> 0 | AE10: =IF(H10="Critical",4,IF(H10="High",3,IF(H10="Medium",2,IF(H10="Low",1,0)))) -> 4 | AF10: =(1-AA10)*100+AE10*8+IF(I10<=2,8,0) -> 140
A11: ='Unit 1 Tracker'!A11 -> U1-07 | B11: ='Unit 1 Tracker'!B11 -> Unit 1 | C11: ='Unit 1 Tracker'!C11 -> Malthusian trap, subsistence, and technology shock | D11: ='Unit 1 Tracker'!D11 -> Orange | E11: ='Unit 1 Tracker'!E11 -> Merged | F11: ='Unit 1 Tracker'!F11 -> A1 | G11: ='Unit 1 Tracker'!G11 -> 0 | H11: ='Unit 1 Tracker'!H11 -> Critical | ... AD11: ='Unit 1 Tracker'!AD11 -> 0 | AE11: =IF(H11="Critical",4,IF(H11="High",3,IF(H11="Medium",2,IF(H11="Low",1,0)))) -> 4 | AF11: =(1-AA11)*100+AE11*8+IF(I11<=2,8,0) -> 140
A12: ='Unit 1 Tracker'!A12 -> U1-08 | B12: ='Unit 1 Tracker'!B12 -> Unit 1 | C12: ='Unit 1 Tracker'!C12 -> Capitalism, institutions, and structural transformation | D12: ='Unit 1 Tracker'!D12 -> Red | E12: ='Unit 1 Tracker'!E12 -> Merged | F12: ='Unit 1 Tracker'!F12 -> A1 | G12: ='Unit 1 Tracker'!G12 -> 0 | H12: ='Unit 1 Tracker'!H12 -> Critical | ... AD12: ='Unit 1 Tracker'!AD12 -> 0 | AE12: =IF(H12="Critical",4,IF(H12="High",3,IF(H12="Medium",2,IF(H12="Low",1,0)))) -> 4 | AF12: =(1-AA12)*100+AE12*8+IF(I12<=2,8,0) -> 140
A13: ='Unit 1 Tracker'!A13 -> U1-09 | B13: ='Unit 1 Tracker'!B13 -> Unit 1 | C13: ='Unit 1 Tracker'!C13 -> Colonization, varieties of capitalism, and the biosphere | D13: ='Unit 1 Tracker'!D13 -> Pink | E13: ='Unit 1 Tracker'!E13 -> Merged | F13: ='Unit 1 Tracker'!F13 -> A1 | G13: ='Unit 1 Tracker'!G13 -> 0 | H13: ='Unit 1 Tracker'!H13 -> High | ... AD13: ='Unit 1 Tracker'!AD13 -> 0 | AE13: =IF(H13="Critical",4,IF(H13="High",3,IF(H13="Medium",2,IF(H13="Low",1,0)))) -> 3 | AF13: =(1-AA13)*100+AE13*8+IF(I13<=2,8,0) -> 132
A14: ='Unit 2 Tracker'!A5 -> U2-01 | B14: ='Unit 2 Tracker'!B5 -> Unit 2 | C14: ='Unit 2 Tracker'!C5 -> Kutesmart, automation, and the opening technology story | D14: ='Unit 2 Tracker'!D5 -> Purple | E14: ='Unit 2 Tracker'!E5 -> Merged | F14: ='Unit 2 Tracker'!F5 -> A1 | G14: ='Unit 2 Tracker'!G5 -> 0 | H14: ='Unit 2 Tracker'!H5 -> Medium | ... AD14: ='Unit 2 Tracker'!AD5 -> 0 | AE14: =IF(H14="Critical",4,IF(H14="High",3,IF(H14="Medium",2,IF(H14="Low",1,0)))) -> 2 | AF14: =(1-AA14)*100+AE14*8+IF(I14<=2,8,0) -> 124
A15: ='Unit 2 Tracker'!A6 -> U2-02 | B15: ='Unit 2 Tracker'!B6 -> Unit 2 | C15: ='Unit 2 Tracker'!C6 -> Opportunity cost, economic cost, reservation option, and economic rent | D15: ='Unit 2 Tracker'!D6 -> Dark Blue | E15: ='Unit 2 Tracker'!E6 -> Merged | F15: ='Unit 2 Tracker'!F6 -> A1 | G15: ='Unit 2 Tracker'!G6 -> 0 | H15: ='Unit 2 Tracker'!H6 -> Critical | ... AD15: ='Unit 2 Tracker'!AD6 -> 0 | AE15: =IF(H15="Critical",4,IF(H15="High",3,IF(H15="Medium",2,IF(H15="Low",1,0)))) -> 4 | AF15: =(1-AA15)*100+AE15*8+IF(I15<=2,8,0) -> 140
A16: ='Unit 2 Tracker'!A7 -> U2-03 | B16: ='Unit 2 Tracker'!B7 -> Unit 2 | C16: ='Unit 2 Tracker'!C7 -> Relative prices | D16: ='Unit 2 Tracker'!D7 -> Light Blue | E16: ='Unit 2 Tracker'!E7 -> Merged | F16: ='Unit 2 Tracker'!F7 -> A1 | G16: ='Unit 2 Tracker'!G7 -> 0 | H16: ='Unit 2 Tracker'!H7 -> High | ... AD16: ='Unit 2 Tracker'!AD7 -> 0 | AE16: =IF(H16="Critical",4,IF(H16="High",3,IF(H16="Medium",2,IF(H16="Low",1,0)))) -> 3 | AF16: =(1-AA16)*100+AE16*8+IF(I16<=2,8,0) -> 132
A17: ='Unit 2 Tracker'!A8 -> U2-04 | B17: ='Unit 2 Tracker'!B8 -> Unit 2 | C17: ='Unit 2 Tracker'!C8 -> Comparative advantage, specialization, and division of labour | D17: ='Unit 2 Tracker'!D8 -> Dark Green | E17: ='Unit 2 Tracker'!E8 -> Merged | F17: ='Unit 2 Tracker'!F8 -> A1 | G17: ='Unit 2 Tracker'!G8 -> 0 | H17: ='Unit 2 Tracker'!H8 -> Critical | ... AD17: ='Unit 2 Tracker'!AD8 -> 0 | AE17: =IF(H17="Critical",4,IF(H17="High",3,IF(H17="Medium",2,IF(H17="Low",1,0)))) -> 4 | AF17: =(1-AA17)*100+AE17*8+IF(I17<=2,8,0) -> 140
A18: ='Unit 2 Tracker'!A9 -> U2-05 | B18: ='Unit 2 Tracker'!B9 -> Unit 2 | C18: ='Unit 2 Tracker'!C9 -> Firms, technology, production, and dominated technologies | D18: ='Unit 2 Tracker'!D9 -> Pastel Green | E18: ='Unit 2 Tracker'!E9 -> Merged | F18: ='Unit 2 Tracker'!F9 -> A1 | G18: ='Unit 2 Tracker'!G9 -> 0 | H18: ='Unit 2 Tracker'!H9 -> High | ... AD18: ='Unit 2 Tracker'!AD9 -> 0 | AE18: =IF(H18="Critical",4,IF(H18="High",3,IF(H18="Medium",2,IF(H18="Low",1,0)))) -> 3 | AF18: =(1-AA18)*100+AE18*8+IF(I18<=2,8,0) -> 132
A19: ='Unit 2 Tracker'!A10 -> U2-06 | B19: ='Unit 2 Tracker'!B10 -> Unit 2 | C19: ='Unit 2 Tracker'!C10 -> Isocost logic and cost-minimizing technology choice | D19: ='Unit 2 Tracker'!D10 -> Pastel Yellow | E19: ='Unit 2 Tracker'!E10 -> Merged | F19: ='Unit 2 Tracker'!F10 -> A1 | G19: ='Unit 2 Tracker'!G10 -> 0 | H19: ='Unit 2 Tracker'!H10 -> Critical | ... AD19: ='Unit 2 Tracker'!AD10 -> 0 | AE19: =IF(H19="Critical",4,IF(H19="High",3,IF(H19="Medium",2,IF(H19="Low",1,0)))) -> 4 | AF19: =(1-AA19)*100+AE19*8+IF(I19<=2,8,0) -> 140
A20: ='Unit 2 Tracker'!A11 -> U2-07 | B20: ='Unit 2 Tracker'!B11 -> Unit 2 | C20: ='Unit 2 Tracker'!C11 -> Innovation and profit / innovation rents | D20: ='Unit 2 Tracker'!D11 -> Orange | E20: ='Unit 2 Tracker'!E11 -> Merged | F20: ='Unit 2 Tracker'!F11 -> A1 | G20: ='Unit 2 Tracker'!G11 -> 0 | H20: ='Unit 2 Tracker'!H11 -> Medium | ... AD20: ='Unit 2 Tracker'!AD11 -> 0 | AE20: =IF(H20="Critical",4,IF(H20="High",3,IF(H20="Medium",2,IF(H20="Low",1,0)))) -> 2 | AF20: =(1-AA20)*100+AE20*8+IF(I20<=2,8,0) -> 124
A21: ='Unit 2 Tracker'!A12 -> U2-08 | B21: ='Unit 2 Tracker'!B12 -> Unit 2 | C21: ='Unit 2 Tracker'!C12 -> Cheap coal, expensive labour, and the Industrial Revolution | D21: ='Unit 2 Tracker'!D12 -> Red | E21: ='Unit 2 Tracker'!E12 -> Merged | F21: ='Unit 2 Tracker'!F12 -> A1 | G21: ='Unit 2 Tracker'!G12 -> 0 | H21: ='Unit 2 Tracker'!H12 -> Critical | ... AD21: ='Unit 2 Tracker'!AD12 -> 0 | AE21: =IF(H21="Critical",4,IF(H21="High",3,IF(H21="Medium",2,IF(H21="Low",1,0)))) -> 4 | AF21: =(1-AA21)*100+AE21*8+IF(I21<=2,8,0) -> 140
A22: ='Unit 2 Tracker'!A13 -> U2-09 | B22: ='Unit 2 Tracker'!B13 -> Unit 2 | C22: ='Unit 2 Tracker'!C13 -> Escape from the Malthusian trap, growth, and capitalism + carbon | D22: ='Unit 2 Tracker'!D13 -> Pink | E22: ='Unit 2 Tracker'!E13 -> Merged | F22: ='Unit 2 Tracker'!F13 -> A1 | G22: ='Unit 2 Tracker'!G13 -> 0 | H22: ='Unit 2 Tracker'!H13 -> High | ... AD22: ='Unit 2 Tracker'!AD13 -> 0 | AE22: =IF(H22="Critical",4,IF(H22="High",3,IF(H22="Medium",2,IF(H22="Low",1,0)))) -> 3 | AF22: =(1-AA22)*100+AE22*8+IF(I22<=2,8,0) -> 132
A23: ='Unit 3 Tracker'!A5 -> U3-01 | B23: ='Unit 3 Tracker'!B5 -> Unit 3 | C23: ='Unit 3 Tracker'!C5 -> Scarcity and the consumer-choice model | D23: ='Unit 3 Tracker'!D5 -> Purple | E23: ='Unit 3 Tracker'!E5 -> Merged | F23: ='Unit 3 Tracker'!F5 -> A1 | G23: ='Unit 3 Tracker'!G5 -> 0 | H23: ='Unit 3 Tracker'!H5 -> High | ... AD23: ='Unit 3 Tracker'!AD5 -> 0 | AE23: =IF(H23="Critical",4,IF(H23="High",3,IF(H23="Medium",2,IF(H23="Low",1,0)))) -> 3 | AF23: =(1-AA23)*100+AE23*8+IF(I23<=2,8,0) -> 132
A24: ='Unit 3 Tracker'!A6 -> U3-02 | B24: ='Unit 3 Tracker'!B6 -> Unit 3 | C24: ='Unit 3 Tracker'!C6 -> Preferences, utility, indifference curves, and diminishing MRS | D24: ='Unit 3 Tracker'!D6 -> Dark Blue | E24: ='Unit 3 Tracker'!E6 -> Merged | F24: ='Unit 3 Tracker'!F6 -> A1 | G24: ='Unit 3 Tracker'!G6 -> 0 | H24: ='Unit 3 Tracker'!H6 -> Critical | ... AD24: ='Unit 3 Tracker'!AD6 -> 0 | AE24: =IF(H24="Critical",4,IF(H24="High",3,IF(H24="Medium",2,IF(H24="Low",1,0)))) -> 4 | AF24: =(1-AA24)*100+AE24*8+IF(I24<=2,8,0) -> 140
A25: ='Unit 3 Tracker'!A7 -> U3-03 | B25: ='Unit 3 Tracker'!B7 -> Unit 3 | C25: ='Unit 3 Tracker'!C7 -> Budget constraints, feasible sets, MRT, and relative prices | D25: ='Unit 3 Tracker'!D7 -> Light Blue | E25: ='Unit 3 Tracker'!E7 -> Merged | F25: ='Unit 3 Tracker'!F7 -> A1 | G25: ='Unit 3 Tracker'!G7 -> 0 | H25: ='Unit 3 Tracker'!H7 -> Critical | ... AD25: ='Unit 3 Tracker'!AD7 -> 0 | AE25: =IF(H25="Critical",4,IF(H25="High",3,IF(H25="Medium",2,IF(H25="Low",1,0)))) -> 4 | AF25: =(1-AA25)*100+AE25*8+IF(I25<=2,8,0) -> 140
A26: ='Unit 3 Tracker'!A8 -> U3-04 | B26: ='Unit 3 Tracker'!B8 -> Unit 3 | C26: ='Unit 3 Tracker'!C8 -> Optimal choice and MRS = MRT | D26: ='Unit 3 Tracker'!D8 -> Dark Green | E26: ='Unit 3 Tracker'!E8 -> Merged | F26: ='Unit 3 Tracker'!F8 -> A1 | G26: ='Unit 3 Tracker'!G8 -> 0 | H26: ='Unit 3 Tracker'!H8 -> Critical | ... AD26: ='Unit 3 Tracker'!AD8 -> 0 | AE26: =IF(H26="Critical",4,IF(H26="High",3,IF(H26="Medium",2,IF(H26="Low",1,0)))) -> 4 | AF26: =(1-AA26)*100+AE26*8+IF(I26<=2,8,0) -> 140
A27: ='Unit 3 Tracker'!A9 -> U3-05 | B27: ='Unit 3 Tracker'!B9 -> Unit 3 | C27: ='Unit 3 Tracker'!C9 -> Price effect, income effect, and substitution effect for goods | D27: ='Unit 3 Tracker'!D9 -> Pastel Green | E27: ='Unit 3 Tracker'!E9 -> Merged | F27: ='Unit 3 Tracker'!F9 -> A1 | G27: ='Unit 3 Tracker'!G9 -> 0 | H27: ='Unit 3 Tracker'!H9 -> Critical | ... AD27: ='Unit 3 Tracker'!AD9 -> 0 | AE27: =IF(H27="Critical",4,IF(H27="High",3,IF(H27="Medium",2,IF(H27="Low",1,0)))) -> 4 | AF27: =(1-AA27)*100+AE27*8+IF(I27<=2,8,0) -> 140
A28: ='Unit 3 Tracker'!A10 -> U3-06 | B28: ='Unit 3 Tracker'!B10 -> Unit 3 | C28: ='Unit 3 Tracker'!C10 -> Work, free time, and the labour-supply model | D28: ='Unit 3 Tracker'!D10 -> Pastel Yellow | E28: ='Unit 3 Tracker'!E10 -> Merged | F28: ='Unit 3 Tracker'!F10 -> A1 | G28: ='Unit 3 Tracker'!G10 -> 0 | H28: ='Unit 3 Tracker'!H10 -> High | ... AD28: ='Unit 3 Tracker'!AD10 -> 0 | AE28: =IF(H28="Critical",4,IF(H28="High",3,IF(H28="Medium",2,IF(H28="Low",1,0)))) -> 3 | AF28: =(1-AA28)*100+AE28*8+IF(I28<=2,8,0) -> 132
A29: ='Unit 3 Tracker'!A11 -> U3-07 | B29: ='Unit 3 Tracker'!B11 -> Unit 3 | C29: ='Unit 3 Tracker'!C11 -> Wage changes: income vs substitution effects on hours worked | D29: ='Unit 3 Tracker'!D11 -> Orange | E29: ='Unit 3 Tracker'!E11 -> Merged | F29: ='Unit 3 Tracker'!F11 -> A1 | G29: ='Unit 3 Tracker'!G11 -> 0 | H29: ='Unit 3 Tracker'!H11 -> Critical | ... AD29: ='Unit 3 Tracker'!AD11 -> 0 | AE29: =IF(H29="Critical",4,IF(H29="High",3,IF(H29="Medium",2,IF(H29="Low",1,0)))) -> 4 | AF29: =(1-AA29)*100+AE29*8+IF(I29<=2,8,0) -> 140
A30: ='Unit 3 Tracker'!A12 -> U3-08 | B30: ='Unit 3 Tracker'!B12 -> Unit 3 | C30: ='Unit 3 Tracker'!C12 -> Model limits, country differences, and long-run changes in work hours | D30: ='Unit 3 Tracker'!D12 -> Pink | E30: ='Unit 3 Tracker'!E12 -> Merged | F30: ='Unit 3 Tracker'!F12 -> A1 | G30: ='Unit 3 Tracker'!G12 -> 0 | H30: ='Unit 3 Tracker'!H12 -> Medium | ... AD30: ='Unit 3 Tracker'!AD12 -> 0 | AE30: =IF(H30="Critical",4,IF(H30="High",3,IF(H30="Medium",2,IF(H30="Low",1,0)))) -> 2 | AF30: =(1-AA30)*100+AE30*8+IF(I30<=2,8,0) -> 124
A31: ='Unit 4 Tracker'!A5 -> U4-01 | B31: ='Unit 4 Tracker'!B5 -> Unit 4 | C31: ='Unit 4 Tracker'!C5 -> Climate negotiations, social dilemmas, and tragedy of the commons | D31: ='Unit 4 Tracker'!D5 -> Purple | E31: ='Unit 4 Tracker'!E5 -> Merged | F31: ='Unit 4 Tracker'!F5 -> A1 | G31: ='Unit 4 Tracker'!G5 -> 0 | H31: ='Unit 4 Tracker'!H5 -> Critical | ... AD31: ='Unit 4 Tracker'!AD5 -> 0 | AE31: =IF(H31="Critical",4,IF(H31="High",3,IF(H31="Medium",2,IF(H31="Low",1,0)))) -> 4 | AF31: =(1-AA31)*100+AE31*8+IF(I31<=2,8,0) -> 140
A32: ='Unit 4 Tracker'!A6 -> U4-02 | B32: ='Unit 4 Tracker'!B6 -> Unit 4 | C32: ='Unit 4 Tracker'!C6 -> Game theory basics: players, strategies, payoffs, information | D32: ='Unit 4 Tracker'!D6 -> Dark Blue | E32: ='Unit 4 Tracker'!E6 -> Merged | F32: ='Unit 4 Tracker'!F6 -> A1 | G32: ='Unit 4 Tracker'!G6 -> 0 | H32: ='Unit 4 Tracker'!H6 -> Critical | ... AD32: ='Unit 4 Tracker'!AD6 -> 0 | AE32: =IF(H32="Critical",4,IF(H32="High",3,IF(H32="Medium",2,IF(H32="Low",1,0)))) -> 4 | AF32: =(1-AA32)*100+AE32*8+IF(I32<=2,8,0) -> 140
A33: ='Unit 4 Tracker'!A7 -> U4-03 | B33: ='Unit 4 Tracker'!B7 -> Unit 4 | C33: ='Unit 4 Tracker'!C7 -> Best responses, invisible-hand games, and Nash equilibrium | D33: ='Unit 4 Tracker'!D7 -> Light Blue | E33: ='Unit 4 Tracker'!E7 -> Merged | F33: ='Unit 4 Tracker'!F7 -> A1 | G33: ='Unit 4 Tracker'!G7 -> 0 | H33: ='Unit 4 Tracker'!H7 -> Critical | ... AD33: ='Unit 4 Tracker'!AD7 -> 0 | AE33: =IF(H33="Critical",4,IF(H33="High",3,IF(H33="Medium",2,IF(H33="Low",1,0)))) -> 4 | AF33: =(1-AA33)*100+AE33*8+IF(I33<=2,8,0) -> 140
A34: ='Unit 4 Tracker'!A8 -> U4-04 | B34: ='Unit 4 Tracker'!B8 -> Unit 4 | C34: ='Unit 4 Tracker'!C8 -> Dominant strategies and prisoners' dilemmas | D34: ='Unit 4 Tracker'!D8 -> Dark Green | E34: ='Unit 4 Tracker'!E8 -> Merged | F34: ='Unit 4 Tracker'!F8 -> A1 | G34: ='Unit 4 Tracker'!G8 -> 0 | H34: ='Unit 4 Tracker'!H8 -> Critical | ... AD34: ='Unit 4 Tracker'!AD8 -> 0 | AE34: =IF(H34="Critical",4,IF(H34="High",3,IF(H34="Medium",2,IF(H34="Low",1,0)))) -> 4 | AF34: =(1-AA34)*100+AE34*8+IF(I34<=2,8,0) -> 140
A35: ='Unit 4 Tracker'!A9 -> U4-05 | B35: ='Unit 4 Tracker'!B9 -> Unit 4 | C35: ='Unit 4 Tracker'!C9 -> Pareto criterion, Pareto efficiency, and fairness | D35: ='Unit 4 Tracker'!D9 -> Pastel Green | E35: ='Unit 4 Tracker'!E9 -> Merged | F35: ='Unit 4 Tracker'!F9 -> A1 | G35: ='Unit 4 Tracker'!G9 -> 0 | H35: ='Unit 4 Tracker'!H9 -> High | ... AD35: ='Unit 4 Tracker'!AD9 -> 0 | AE35: =IF(H35="Critical",4,IF(H35="High",3,IF(H35="Medium",2,IF(H35="Low",1,0)))) -> 3 | AF35: =(1-AA35)*100+AE35*8+IF(I35<=2,8,0) -> 132
A36: ='Unit 4 Tracker'!A10 -> U4-06 | B36: ='Unit 4 Tracker'!B10 -> Unit 4 | C36: ='Unit 4 Tracker'!C10 -> Public-good games, free-riding, and Ostrom | D36: ='Unit 4 Tracker'!D10 -> Pastel Yellow | E36: ='Unit 4 Tracker'!E10 -> Merged | F36: ='Unit 4 Tracker'!F10 -> A1 | G36: ='Unit 4 Tracker'!G10 -> 0 | H36: ='Unit 4 Tracker'!H10 -> High | ... AD36: ='Unit 4 Tracker'!AD10 -> 0 | AE36: =IF(H36="Critical",4,IF(H36="High",3,IF(H36="Medium",2,IF(H36="Low",1,0)))) -> 3 | AF36: =(1-AA36)*100+AE36*8+IF(I36<=2,8,0) -> 132
A37: ='Unit 4 Tracker'!A11 -> U4-07 | B37: ='Unit 4 Tracker'!B11 -> Unit 4 | C37: ='Unit 4 Tracker'!C11 -> Social preferences: altruism, reciprocity, inequality aversion | D37: ='Unit 4 Tracker'!D11 -> Orange | E37: ='Unit 4 Tracker'!E11 -> Merged | F37: ='Unit 4 Tracker'!F11 -> A1 | G37: ='Unit 4 Tracker'!G11 -> 0 | H37: ='Unit 4 Tracker'!H11 -> High | ... AD37: ='Unit 4 Tracker'!AD11 -> 0 | AE37: =IF(H37="Critical",4,IF(H37="High",3,IF(H37="Medium",2,IF(H37="Low",1,0)))) -> 3 | AF37: =(1-AA37)*100+AE37*8+IF(I37<=2,8,0) -> 132
A38: ='Unit 4 Tracker'!A12 -> U4-08 | B38: ='Unit 4 Tracker'!B12 -> Unit 4 | C38: ='Unit 4 Tracker'!C12 -> Repeated interaction, experiments, punishment, and crowding out | D38: ='Unit 4 Tracker'!D12 -> Red | E38: ='Unit 4 Tracker'!E12 -> Merged | F38: ='Unit 4 Tracker'!F12 -> A1 | G38: ='Unit 4 Tracker'!G12 -> 0 | H38: ='Unit 4 Tracker'!H12 -> High | ... AD38: ='Unit 4 Tracker'!AD12 -> 0 | AE38: =IF(H38="Critical",4,IF(H38="High",3,IF(H38="Medium",2,IF(H38="Low",1,0)))) -> 3 | AF38: =(1-AA38)*100+AE38*8+IF(I38<=2,8,0) -> 132
A39: ='Unit 4 Tracker'!A13 -> U4-09 | B39: ='Unit 4 Tracker'!B13 -> Unit 4 | C39: ='Unit 4 Tracker'!C13 -> Cooperation, negotiation, and conflicts of interest | D39: ='Unit 4 Tracker'!D13 -> Pink | E39: ='Unit 4 Tracker'!E13 -> Merged | F39: ='Unit 4 Tracker'!F13 -> A1 | G39: ='Unit 4 Tracker'!G13 -> 0 | H39: ='Unit 4 Tracker'!H13 -> Medium | ... AD39: ='Unit 4 Tracker'!AD13 -> 0 | AE39: =IF(H39="Critical",4,IF(H39="High",3,IF(H39="Medium",2,IF(H39="Low",1,0)))) -> 2 | AF39: =(1-AA39)*100+AE39*8+IF(I39<=2,8,0) -> 124
A40: ='Unit 4 Tracker'!A14 -> U4-10 | B40: ='Unit 4 Tracker'!B14 -> Unit 4 | C40: ='Unit 4 Tracker'!C14 -> Ultimatum game, experiments, expected payoffs, and competition | D40: ='Unit 4 Tracker'!D14 -> Purple | E40: ='Unit 4 Tracker'!E14 -> Merged | F40: ='Unit 4 Tracker'!F14 -> A1 | G40: ='Unit 4 Tracker'!G14 -> 0 | H40: ='Unit 4 Tracker'!H14 -> Critical | ... AD40: ='Unit 4 Tracker'!AD14 -> 0 | AE40: =IF(H40="Critical",4,IF(H40="High",3,IF(H40="Medium",2,IF(H40="Low",1,0)))) -> 4 | AF40: =(1-AA40)*100+AE40*8+IF(I40<=2,8,0) -> 140
A41: ='Unit 4 Tracker'!A15 -> U4-11 | B41: ='Unit 4 Tracker'!B15 -> Unit 4 | C41: ='Unit 4 Tracker'!C15 -> Coordination games, hawk–dove, and climate-change modelling | D41: ='Unit 4 Tracker'!D15 -> Dark Blue | E41: ='Unit 4 Tracker'!E15 -> Merged | F41: ='Unit 4 Tracker'!F15 -> A1 | G41: ='Unit 4 Tracker'!G15 -> 0 | H41: ='Unit 4 Tracker'!H15 -> Critical | ... AD41: ='Unit 4 Tracker'!AD15 -> 0 | AE41: =IF(H41="Critical",4,IF(H41="High",3,IF(H41="Medium",2,IF(H41="Low",1,0)))) -> 4 | AF41: =(1-AA41)*100+AE41*8+IF(I41<=2,8,0) -> 140

Sheet Graph Tracker
A1: Graph Tracker
A2: Track whether you can explain each graph, not just recognize it.
A4: Graph ID | B4: Unit | C4: Graph / visual | D4: Linked topic | E4: A1 tag | F4: A2 tag | G4: Seen? | H4: Axes? | I4: Shape? | J4: Exam meaning? | K4: Mastered? | L4: Confidence | M4: Est mins | N4: Notes
A5: G-U1-01 | B5: Unit 1 | C5: History's hockey stick | D5: GDP, GDP per capita, and history's hockey stick | E5: A1 | G5: Yes | H5: Yes | I5: Yes | J5: No | K5: No | L5: 1 | M5: 20
A6: G-U1-02 | B6: Unit 1 | C6: Between-country inequality | D6: Between-country and within-country inequality | E6: A1 | G6: No | H6: No | I6: No | J6: No | K6: No | L6: 1 | M6: 15
A7: G-U1-03 | B7: Unit 1 | C7: Within-country inequality | D7: Between-country and within-country inequality | E7: A1 | G7: No | H7: No | I7: No | J7: No | K7: No | L7: 1 | M7: 15
A8: G-U1-04 | B8: Unit 1 | C8: Climate cost / climate hockey-stick logic | D8: Climate change and the cost of economic development | E8: A1 | G8: No | H8: No | I8: No | J8: No | K8: No | L8: 1 | M8: 20
A9: G-U1-05 | B9: Unit 1 | C9: Technological revolution examples | D9: Continuous technological revolution | E9: A1 | G9: No | H9: No | I9: No | J9: No | K9: No | L9: 1 | M9: 10
A10: G-U1-06 | B10: Unit 1 | C10: Production function / diminishing APL | D10: Production function and diminishing average product of labour | E10: A1 | G10: No | H10: No | I10: No | J10: No | K10: No | L10: 1 | M10: 20
A11: G-U1-07 | B11: Unit 1 | C11: Malthusian equilibrium | D11: Malthusian trap, subsistence, and technology shock | E11: A1 | G11: No | H11: No | I11: No | J11: No | K11: No | L11: 1 | M11: 25
A12: G-U1-08 | B12: Unit 1 | C12: Malthusian technology improvement | D12: Malthusian trap, subsistence, and technology shock | E12: A1 | G12: No | H12: No | I12: No | J12: No | K12: No | L12: 1 | M12: 25
A13: G-U1-09 | B13: Unit 1 | C13: Structural transformation / non-agricultural labour | D13: Capitalism, institutions, and structural transformation | E13: A1 | G13: No | H13: No | I13: No | J13: No | K13: No | L13: 1 | M13: 15
A14: G-U1-10 | B14: Unit 1 | C14: Biodiversity loss scenarios | D14: Colonization, varieties of capitalism, and the biosphere | E14: A1 | G14: No | H14: No | I14: No | J14: No | K14: No | L14: 1 | M14: 15
A15: G-U2-01 | B15: Unit 2 | C15: Real wages and population over time | D15: Cheap coal, expensive labour, and the Industrial Revolution | E15: A1 | G15: No | H15: No | I15: No | J15: No | K15: No | L15: 1 | M15: 20
A16: G-U2-02 | B16: Unit 2 | C16: Opportunity cost / economic cost | D16: Opportunity cost, economic cost, reservation option, and economic rent | E16: A1 | G16: No | H16: No | I16: No | J16: No | K16: No | L16: 1 | M16: 15
... A31: G-U4-06 | B31: Unit 4 | C31: Coordination / climate game | D31: Coordination games, hawk–dove, and climate-change modelling | E31: A1 | G31: No | H31: No | I31: No | J31: No | K31: No | L31: 1 | M31: 20

Sheet Tutorial Tracker
A1: Tutorial Tracker
A2: Track attempts, redos, and whether you extracted teach-back explanations from tutorials.
A4: Tutorial ID | B4: Unit | C4: Tutorial / question cluster | D4: Linked topic | E4: A1 tag | F4: A2 tag | G4: Attempted? | H4: Confidence | I4: Redo? | J4: Teach-back extracted? | K4: Est mins | L4: Status | M4: Notes
A5: T1-01 | B5: Unit 1 | C5: Tutorial 1: definitions + hockey-stick timing | D5: GDP, GDP per capita, and history's hockey stick | E5: A1 | G5: No | H5: 1 | I5: Yes | J5: No | K5: 40 | L5: Not started
A6: T1-02 | B6: Unit 1 | C6: Tutorial 1: capitalism + Malthusian model | D6: Malthusian trap, subsistence, and technology shock | E6: A1 | G6: No | H6: 1 | I6: Yes | J6: No | K6: 45 | L6: Not started
A7: T2-01 | B7: Unit 2 | C7: Tutorial 2: opportunity cost / rent / relative prices | D7: Opportunity cost, economic cost, reservation option, and economic rent | E7: A1 | G7: No | H7: 1 | I7: Yes | J7: No | K7: 45 | L7: Not started
A8: T2-02 | B8: Unit 2 | C8: Tutorial 2: technology choice and labour-price changes | D8: Isocost logic and cost-minimizing technology choice | E8: A1 | G8: No | H8: 1 | I8: Yes | J8: No | K8: 50 | L8: Not started
A9: T3-01 | B9: Unit 3 | C9: Tutorial 3: ICs, MRS, and budget lines | D9: Preferences, utility, indifference curves, and diminishing MRS | E9: A1 | G9: No | H9: 1 | I9: Yes | J9: No | K9: 45 | L9: Not started
A10: T3-02 | B10: Unit 3 | C10: Tutorial 3: work/free-time and wage effects | D10: Wage changes: income vs substitution effects on hours worked | E10: A1 | G10: No | H10: 1 | I10: Yes | J10: No | K10: 50 | L10: Not started
A11: T4-01 | B11: Unit 4 | C11: Unit 4 matrix drills | D11: Best responses, invisible-hand games, and Nash equilibrium | E11: A1 | G11: No | H11: 1 | I11: Yes | J11: No | K11: 45 | L11: Not started
A12: T4-02 | B12: Unit 4 | C12: Unit 4 Pareto/public goods/ultimatum/climate drills | D12: Coordination games, hawk–dove, and climate-change modelling | E12: A1 | G12: No | H12: 1 | I12: Yes | J12: No | K12: 60 | L12: Not started

Sheet Session Log
A1: Session Log
A2: Log actual study blocks so the workbook can calculate weekly hours and real progress.
A4: Date | B4: Week start | C4: Unit | D4: Topic | E4: Method | F4: Assessment focus | G4: Planned mins | H4: Actual mins | I4: Energy | J4: Confidence after | K4: Could teach? | L4: Next action / reflection
B5: =IF(A5="","",A5-WEEKDAY(A5,2)+1)
B6: =IF(A6="","",A6-WEEKDAY(A6,2)+1)
B7: =IF(A7="","",A7-WEEKDAY(A7,2)+1)
B8: =IF(A8="","",A8-WEEKDAY(A8,2)+1)
B9: =IF(A9="","",A9-WEEKDAY(A9,2)+1)
B10: =IF(A10="","",A10-WEEKDAY(A10,2)+1)
B11: =IF(A11="","",A11-WEEKDAY(A11,2)+1)
B12: =IF(A12="","",A12-WEEKDAY(A12,2)+1)
B13: =IF(A13="","",A13-WEEKDAY(A13,2)+1)
B14: =IF(A14="","",A14-WEEKDAY(A14,2)+1)
B15: =IF(A15="","",A15-WEEKDAY(A15,2)+1)
B16: =IF(A16="","",A16-WEEKDAY(A16,2)+1)
... B124: =IF(A124="","",A124-WEEKDAY(A124,2)+1)

Sheet Weak Spots
A1: Weak Spots / Mistakes Log
A2: Write the reason for the mistake and the corrected explanation so retesting becomes useful.
A4: Date | B4: Unit | C4: Topic | D4: Mistake made | E4: Why it happened | F4: Corrected explanation | G4: Retest date | H4: Retested? | I4: Assessment | J4: Status

Sheet Readiness
A1: Readiness Engine
A2: Auto-summary by unit. A2 remains blank until those tags are populated.
A4: Unit | B4: Estimated hours | C4: Remaining hours | D4: Hours logged | E4: Avg progress | F4: Avg confidence | G4: Graphs mastered % | H4: Tutorials attempted % | I4: Exam-ready % | J4: A1 readiness | K4: A2 readiness | L4: Suggested next move
A5: Unit 1 | B5: =SUM('Unit 1 Tracker'!Z5:Z13)/60 -> 16.25 | C5: =SUM('Unit 1 Tracker'!AB5:AB13)/60 -> 14.90625 | D5: =SUMIFS('Session Log'!H:H,'Session Log'!C:C,A5)/60 -> 0 | E5: =AVERAGE('Unit 1 Tracker'!AA5:AA13) -> 0.097222222 | F5: =AVERAGE('Unit 1 Tracker'!I5:I13) -> 1 | G5: =COUNTIFS('Graph Tracker'!B:B,A5,'Graph Tracker'!K:K,"Yes")/COUNTIF('Graph Tracker'!B:B,A5) -> 0 | H5: =COUNTIFS('Tutorial Tracker'!B:B,A5,'Tutorial Tracker'!G:G,"Yes")/COUNTIF('Tutorial Tracker'!B:B,A5) -> 0 | I5: =COUNTIF('Unit 1 Tracker'!R5:R13,"Yes")/ROWS('Unit 1 Tracker'!R5:R13) -> 0 | J5: =AVERAGE(E5,H5,I5,MIN(F5/5,1),G5) -> 0.059444444 | K5: =IF(COUNTIF('Unit 1 Tracker'!G5:G13,"A2")+COUNTIF('Unit 1 Tracker'!G5:G13,"Both")=0,"",AVERAGE(E5,I5,MIN(F5/5,1))) | L5: =IF(J5<0.35,"Build notes + recall",IF(J5<0.65,"Push tutorials + graphs","Shift to mixed exam drills")) -> Build notes + recall
A6: Unit 2 | B6: =SUM('Unit 2 Tracker'!Z5:Z13)/60 -> 16.666667 | C6: =SUM('Unit 2 Tracker'!AB5:AB13)/60 -> 16.666667 | D6: =SUMIFS('Session Log'!H:H,'Session Log'!C:C,A6)/60 -> 0 | E6: =AVERAGE('Unit 2 Tracker'!AA5:AA13) -> 0 | F6: =AVERAGE('Unit 2 Tracker'!I5:I13) -> 1 | G6: =COUNTIFS('Graph Tracker'!B:B,A6,'Graph Tracker'!K:K,"Yes")/COUNTIF('Graph Tracker'!B:B,A6) -> 0 | H6: =COUNTIFS('Tutorial Tracker'!B:B,A6,'Tutorial Tracker'!G:G,"Yes")/COUNTIF('Tutorial Tracker'!B:B,A6) -> 0 | I6: =COUNTIF('Unit 2 Tracker'!R5:R13,"Yes")/ROWS('Unit 2 Tracker'!R5:R13) -> 0 | J6: =AVERAGE(E6,H6,I6,MIN(F6/5,1),G6) -> 0.04 | K6: =IF(COUNTIF('Unit 2 Tracker'!G5:G13,"A2")+COUNTIF('Unit 2 Tracker'!G5:G13,"Both")=0,"",AVERAGE(E6,I6,MIN(F6/5,1))) | L6: =IF(J6<0.35,"Build notes + recall",IF(J6<0.65,"Push tutorials + graphs","Shift to mixed exam drills")) -> Build notes + recall
A7: Unit 3 | B7: =SUM('Unit 3 Tracker'!Z5:Z12)/60 -> 16.333333 | C7: =SUM('Unit 3 Tracker'!AB5:AB12)/60 -> 16.333333 | D7: =SUMIFS('Session Log'!H:H,'Session Log'!C:C,A7)/60 -> 0 | E7: =AVERAGE('Unit 3 Tracker'!AA5:AA12) -> 0 | F7: =AVERAGE('Unit 3 Tracker'!I5:I12) -> 1 | G7: =COUNTIFS('Graph Tracker'!B:B,A7,'Graph Tracker'!K:K,"Yes")/COUNTIF('Graph Tracker'!B:B,A7) -> 0 | H7: =COUNTIFS('Tutorial Tracker'!B:B,A7,'Tutorial Tracker'!G:G,"Yes")/COUNTIF('Tutorial Tracker'!B:B,A7) -> 0 | I7: =COUNTIF('Unit 3 Tracker'!R5:R12,"Yes")/ROWS('Unit 3 Tracker'!R5:R12) -> 0 | J7: =AVERAGE(E7,H7,I7,MIN(F7/5,1),G7) -> 0.04 | K7: =IF(COUNTIF('Unit 3 Tracker'!G5:G12,"A2")+COUNTIF('Unit 3 Tracker'!G5:G12,"Both")=0,"",AVERAGE(E7,I7,MIN(F7/5,1))) | L7: =IF(J7<0.35,"Build notes + recall",IF(J7<0.65,"Push tutorials + graphs","Shift to mixed exam drills")) -> Build notes + recall
A8: Unit 4 | B8: =SUM('Unit 4 Tracker'!Z5:Z15)/60 -> 23 | C8: =SUM('Unit 4 Tracker'!AB5:AB15)/60 -> 23 | D8: =SUMIFS('Session Log'!H:H,'Session Log'!C:C,A8)/60 -> 0 | E8: =AVERAGE('Unit 4 Tracker'!AA5:AA15) -> 0 | F8: =AVERAGE('Unit 4 Tracker'!I5:I15) -> 1 | G8: =COUNTIFS('Graph Tracker'!B:B,A8,'Graph Tracker'!K:K,"Yes")/COUNTIF('Graph Tracker'!B:B,A8) -> 0 | H8: =COUNTIFS('Tutorial Tracker'!B:B,A8,'Tutorial Tracker'!G:G,"Yes")/COUNTIF('Tutorial Tracker'!B:B,A8) -> 0 | I8: =COUNTIF('Unit 4 Tracker'!R5:R15,"Yes")/ROWS('Unit 4 Tracker'!R5:R15) -> 0 | J8: =AVERAGE(E8,H8,I8,MIN(F8/5,1),G8) -> 0.04 | K8: =IF(COUNTIF('Unit 4 Tracker'!G5:G15,"A2")+COUNTIF('Unit 4 Tracker'!G5:G15,"Both")=0,"",AVERAGE(E8,I8,MIN(F8/5,1))) | L8: =IF(J8<0.35,"Build notes + recall",IF(J8<0.65,"Push tutorials + graphs","Shift to mixed exam drills")) -> Build notes + recall

Sheet Action Queue
A1: Action Queue
A2: Starter queue ranked by priority and estimated workload. You can manually re-sort this later if your priorities change.
A4: Topic ID | B4: Unit | C4: Topic / subtopic | D4: Priority | E4: Current progress | F4: Est hours | G4: Source tracker row | H4: Next action
A5: ='Unit 4 Tracker'!A14 -> U4-10 | B5: ='Unit 4 Tracker'!B14 -> Unit 4 | C5: ='Unit 4 Tracker'!C14 -> Ultimatum game, experiments, expected payoffs, and competition | D5: ='Unit 4 Tracker'!H14 -> Critical | E5: ='Unit 4 Tracker'!AA14 -> 0 | F5: ='Unit 4 Tracker'!Z14/60 -> 2.5833333 | G5: Unit 4 Tracker!14 | H5: ='Unit 4 Tracker'!AC14 -> Sequential solve first, then experimental results
A6: ='Unit 4 Tracker'!A15 -> U4-11 | B6: ='Unit 4 Tracker'!B15 -> Unit 4 | C6: ='Unit 4 Tracker'!C15 -> Coordination games, hawk–dove, and climate-change modelling | D6: ='Unit 4 Tracker'!H15 -> Critical | E6: ='Unit 4 Tracker'!AA15 -> 0 | F6: ='Unit 4 Tracker'!Z15/60 -> 2.5833333 | G6: Unit 4 Tracker!15 | H6: ='Unit 4 Tracker'!AC15 -> Distinguish PD vs coordination vs hawk–dove
A7: ='Unit 3 Tracker'!A9 -> U3-05 | B7: ='Unit 3 Tracker'!B9 -> Unit 3 | C7: ='Unit 3 Tracker'!C9 -> Price effect, income effect, and substitution effect for goods | D7: ='Unit 3 Tracker'!H9 -> Critical | E7: ='Unit 3 Tracker'!AA9 -> 0 | F7: ='Unit 3 Tracker'!Z9/60 -> 2.5 | G7: Unit 3 Tracker!9 | H7: ='Unit 3 Tracker'!AC9 -> Be able to separate the two effects cleanly
A8: ='Unit 1 Tracker'!A11 -> U1-07 | B8: ='Unit 1 Tracker'!B11 -> Unit 1 | C8: ='Unit 1 Tracker'!C11 -> Malthusian trap, subsistence, and technology shock | D8: ='Unit 1 Tracker'!H11 -> Critical | E8: ='Unit 1 Tracker'!AA11 -> 0 | F8: ='Unit 1 Tracker'!Z11/60 -> 2.3333333 | G8: Unit 1 Tracker!11 | H8: ='Unit 1 Tracker'!AC11 -> Practise the four-step mechanism aloud
A9: ='Unit 3 Tracker'!A6 -> U3-02 | B9: ='Unit 3 Tracker'!B6 -> Unit 3 | C9: ='Unit 3 Tracker'!C6 -> Preferences, utility, indifference curves, and diminishing MRS | D9: ='Unit 3 Tracker'!H6 -> Critical | E9: ='Unit 3 Tracker'!AA6 -> 0 | F9: ='Unit 3 Tracker'!Z6/60 -> 2.3333333 | G9: Unit 3 Tracker!6 | H9: ='Unit 3 Tracker'!AC6 -> Do not let ICs shift when budget changes
A10: ='Unit 3 Tracker'!A7 -> U3-03 | B10: ='Unit 3 Tracker'!B7 -> Unit 3 | C10: ='Unit 3 Tracker'!C7 -> Budget constraints, feasible sets, MRT, and relative prices | D10: ='Unit 3 Tracker'!H7 -> Critical | E10: ='Unit 3 Tracker'!AA7 -> 0 | F10: ='Unit 3 Tracker'!Z7/60 -> 2.3333333 | G10: Unit 3 Tracker!7 | H10: ='Unit 3 Tracker'!AC7 -> Write the line equation from scratch
A11: ='Unit 2 Tracker'!A10 -> U2-06 | B11: ='Unit 2 Tracker'!B10 -> Unit 2 | C11: ='Unit 2 Tracker'!C10 -> Isocost logic and cost-minimizing technology choice | D11: ='Unit 2 Tracker'!H10 -> Critical | E11: ='Unit 2 Tracker'!AA10 -> 0 | F11: ='Unit 2 Tracker'!Z10/60 -> 2.25 | G11: Unit 2 Tracker!10 | H11: ='Unit 2 Tracker'!AC10 -> Use wage/capital-price changes carefully
A12: ='Unit 2 Tracker'!A12 -> U2-08 | B12: ='Unit 2 Tracker'!B12 -> Unit 2 | C12: ='Unit 2 Tracker'!C12 -> Cheap coal, expensive labour, and the Industrial Revolution | D12: ='Unit 2 Tracker'!H12 -> Critical | E12: ='Unit 2 Tracker'!AA12 -> 0 | F12: ='Unit 2 Tracker'!Z12/60 -> 2.25 | G12: Unit 2 Tracker!12 | H12: ='Unit 2 Tracker'!AC12 -> Explain incentives, not just inventions
A13: ='Unit 3 Tracker'!A11 -> U3-07 | B13: ='Unit 3 Tracker'!B11 -> Unit 3 | C13: ='Unit 3 Tracker'!C11 -> Wage changes: income vs substitution effects on hours worked | D13: ='Unit 3 Tracker'!H11 -> Critical | E13: ='Unit 3 Tracker'!AA11 -> 0 | F13: ='Unit 3 Tracker'!Z11/60 -> 2.25 | G13: Unit 3 Tracker!11 | H13: ='Unit 3 Tracker'!AC11 -> Dominant effect depends on behaviour
A14: ='Unit 1 Tracker'!A12 -> U1-08 | B14: ='Unit 1 Tracker'!B12 -> Unit 1 | C14: ='Unit 1 Tracker'!C12 -> Capitalism, institutions, and structural transformation | D14: ='Unit 1 Tracker'!H12 -> Critical | E14: ='Unit 1 Tracker'!AA12 -> 0 | F14: ='Unit 1 Tracker'!Z12/60 -> 2.1666667 | G14: Unit 1 Tracker!12 | H14: ='Unit 1 Tracker'!AC12 -> Use private property + firms + markets
A15: ='Unit 4 Tracker'!A7 -> U4-03 | B15: ='Unit 4 Tracker'!B7 -> Unit 4 | C15: ='Unit 4 Tracker'!C7 -> Best responses, invisible-hand games, and Nash equilibrium | D15: ='Unit 4 Tracker'!H7 -> Critical | E15: ='Unit 4 Tracker'!AA7 -> 0 | F15: ='Unit 4 Tracker'!Z7/60 -> 2.1666667 | G15: Unit 4 Tracker!7 | H15: ='Unit 4 Tracker'!AC7 -> Best response first, equilibrium second
A16: ='Unit 4 Tracker'!A8 -> U4-04 | B16: ='Unit 4 Tracker'!B8 -> Unit 4 | C16: ='Unit 4 Tracker'!C8 -> Dominant strategies and prisoners' dilemmas | D16: ='Unit 4 Tracker'!H8 -> Critical | E16: ='Unit 4 Tracker'!AA8 -> 0 | F16: ='Unit 4 Tracker'!Z8/60 -> 2.1666667 | G16: Unit 4 Tracker!8 | H16: ='Unit 4 Tracker'!AC8 -> Show why stable can still be socially bad
A17: ='Unit 2 Tracker'!A8 -> U2-04 | B17: ='Unit 2 Tracker'!B8 -> Unit 2 | C17: ='Unit 2 Tracker'!C8 -> Comparative advantage, specialization, and division of labour | D17: ='Unit 2 Tracker'!H8 -> Critical | E17: ='Unit 2 Tracker'!AA8 -> 0 | F17: ='Unit 2 Tracker'!Z8/60 -> 2.0833333 | G17: Unit 2 Tracker!8 | H17: ='Unit 2 Tracker'!AC8 -> Always talk in terms of opportunity cost
A18: ='Unit 2 Tracker'!A6 -> U2-02 | B18: ='Unit 2 Tracker'!B6 -> Unit 2 | C18: ='Unit 2 Tracker'!C6 -> Opportunity cost, economic cost, reservation option, and economic rent | D18: ='Unit 2 Tracker'!H6 -> Critical | E18: ='Unit 2 Tracker'!AA6 -> 0 | F18: ='Unit 2 Tracker'!Z6/60 -> 2 | G18: Unit 2 Tracker!6 | H18: ='Unit 2 Tracker'!AC6 -> Practise the Sipho/concert-style logic
A19: ='Unit 1 Tracker'!A5 -> U1-01 | B19: ='Unit 1 Tracker'!B5 -> Unit 1 | C19: ='Unit 1 Tracker'!C5 -> GDP, GDP per capita, and history's hockey stick | D19: ='Unit 1 Tracker'!H5 -> Critical | E19: ='Unit 1 Tracker'!AA5 -> 0.25 | F19: ='Unit 1 Tracker'!Z5/60 -> 1.9166667 | G19: Unit 1 Tracker!5 | H19: ='Unit 1 Tracker'!AC5 -> Start with definitions + hockey-stick graph
A20: ='Unit 1 Tracker'!A10 -> U1-06 | B20: ='Unit 1 Tracker'!B10 -> Unit 1 | C20: ='Unit 1 Tracker'!C10 -> Production function and diminishing average product of labour | D20: ='Unit 1 Tracker'!H10 -> Critical | E20: ='Unit 1 Tracker'!AA10 -> 0 | F20: ='Unit 1 Tracker'!Z10/60 -> 1.9166667 | G20: Unit 1 Tracker!10 | H20: ='Unit 1 Tracker'!AC10 -> Separate total output from output per worker
A21: ='Unit 3 Tracker'!A8 -> U3-04 | B21: ='Unit 3 Tracker'!B8 -> Unit 3 | C21: ='Unit 3 Tracker'!C8 -> Optimal choice and MRS = MRT | D21: ='Unit 3 Tracker'!H8 -> Critical | E21: ='Unit 3 Tracker'!AA8 -> 0 | F21: ='Unit 3 Tracker'!Z8/60 -> 1.9166667 | G21: Unit 3 Tracker!8 | H21: ='Unit 3 Tracker'!AC8 -> Explain highest attainable IC
A22: ='Unit 4 Tracker'!A6 -> U4-02 | B22: ='Unit 4 Tracker'!B6 -> Unit 4 | C22: ='Unit 4 Tracker'!C6 -> Game theory basics: players, strategies, payoffs, information | D22: ='Unit 4 Tracker'!H6 -> Critical | E22: ='Unit 4 Tracker'!AA6 -> 0 | F22: ='Unit 4 Tracker'!Z6/60 -> 1.8333333 | G22: Unit 4 Tracker!6 | H22: ='Unit 4 Tracker'!AC6 -> Read matrices carefully before solving
A23: ='Unit 4 Tracker'!A5 -> U4-01 | B23: ='Unit 4 Tracker'!B5 -> Unit 4 | C23: ='Unit 4 Tracker'!C5 -> Climate negotiations, social dilemmas, and tragedy of the commons | D23: ='Unit 4 Tracker'!H5 -> Critical | E23: ='Unit 4 Tracker'!AA5 -> 0 | F23: ='Unit 4 Tracker'!Z5/60 -> 1.6666667 | G23: Unit 4 Tracker!5 | H23: ='Unit 4 Tracker'!AC5 -> Start with the definition of a social dilemma
A24: ='Unit 1 Tracker'!A13 -> U1-09 | B24: ='Unit 1 Tracker'!B13 -> Unit 1 | C24: ='Unit 1 Tracker'!C13 -> Colonization, varieties of capitalism, and the biosphere | D24: ='Unit 1 Tracker'!H13 -> High | E24: ='Unit 1 Tracker'!AA13 -> 0 | F24: ='Unit 1 Tracker'!Z13/60 -> 2.25 | G24: Unit 1 Tracker!13 | H24: ='Unit 1 Tracker'!AC13 -> Link history, institutions, and environmental limits

Sheet Dashboard
A1: ECON 114 Study OS — Units 1 to 4
A2: Pastel planning dashboard: completion, logged time, readiness, queue, weak spots, and next moves.
A4: Overall % complete | J4: Hours studied this week
A5: =AVERAGE('Master Planner'!AA5:AA200) -> 0.023648649 | J5: =SUMIFS('Session Log'!H:H,'Session Log'!A:A,">="&TODAY()-WEEKDAY(TODAY(),2)+1,'Session Log'!A:A,"<="&TODAY())/60 -> 0
A11: Unit | B11: Est hrs | C11: Remain hrs | D11: Logged hrs | E11: Progress | F11: Confidence | G11: Graphs | H11: Tutorials | I11: Exam-ready | J11: A1 readiness | K11: A2 readiness | L11: Next move | N11: Useful extras
A12: =Readiness!A5 -> Unit 1 | B12: =Readiness!B5 -> 16.25 | C12: =Readiness!C5 -> 14.90625 | D12: =Readiness!D5 -> 0 | E12: =Readiness!E5 -> 0.097222222 | F12: =Readiness!F5 -> 1 | G12: =Readiness!G5 -> 0 | H12: =Readiness!H5 -> 0 | ... L12: =Readiness!L5 -> Build notes + recall | N12: Weak-spot items open | P12: =COUNTIF('Weak Spots'!J:J,"Open")+COUNTIF('Weak Spots'!J:J,"Retest scheduled") -> 0
A13: =Readiness!A6 -> Unit 2 | B13: =Readiness!B6 -> 16.666667 | C13: =Readiness!C6 -> 16.666667 | D13: =Readiness!D6 -> 0 | E13: =Readiness!E6 -> 0 | F13: =Readiness!F6 -> 1 | G13: =Readiness!G6 -> 0 | H13: =Readiness!H6 -> 0 | ... L13: =Readiness!L6 -> Build notes + recall | N13: Total hours left | P13: =SUM(Readiness!C5:C8) -> 70.90625
A14: =Readiness!A7 -> Unit 3 | B14: =Readiness!B7 -> 16.333333 | C14: =Readiness!C7 -> 16.333333 | D14: =Readiness!D7 -> 0 | E14: =Readiness!E7 -> 0 | F14: =Readiness!F7 -> 1 | G14: =Readiness!G7 -> 0 | H14: =Readiness!H7 -> 0 | ... L14: =Readiness!L7 -> Build notes + recall | N14: Graph mastery overall | P14: =COUNTIF('Graph Tracker'!K:K,"Yes")/COUNTIF('Graph Tracker'!A:A,"<>") -> 0
